mail: name 'datetime' is not defined
Error sending email: name 'datetime' is not defined
Error sending email: name 'datetime' is not defined
Error sending email: name 'datetime' is not defined
Error sending email: name 'datetime' is not defined
Error sending email: name 'datetime' is not defined
Error sending email: name 'datetime' is not defined
Error sending email: name 'datetime' is not defined
^C[2025-03-27 14:14:54 +0000] [415] [INFO] Handling signal: int
[2025-03-27 14:14:54 +0000] [426] [ERROR] Error handling request /login
Traceback (most recent call last):
  File "/home/runner/workspace/.pythonlibs/lib/python3.11/site-packages/flask_mail/__init__.py", line 540, in send
    message.send(connection)
  File "/home/runner/workspace/.pythonlibs/lib/python3.11/site-packages/flask_mail/__init__.py", line 482, in send
    connection.send(self)
  File "/home/runner/workspace/.pythonlibs/lib/python3.11/site-packages/flask_mail/__init__.py", line 177, in send
    self.host.sendmail(
  File "/nix/store/clx0mcir7qw8zk36zbr4jra789g3knf6-python3-3.11.10/lib/python3.11/smtplib.py", line 892, in sendmail
    (code, resp) = self.rcpt(each, rcpt_options)
                   ^^^^^^^^^^^^^^^^^^^^^^^^^^^^^
  File "/nix/store/clx0mcir7qw8zk36zbr4jra789g3knf6-python3-3.11.10/lib/python3.11/smtplib.py", line 554, in rcpt
    return self.getreply()
           ^^^^^^^^^^^^^^^
  File "/nix/store/clx0mcir7qw8zk36zbr4jra789g3knf6-python3-3.11.10/lib/python3.11/smtplib.py", line 398, in getreply
    line = self.file.readline(_MAXLINE + 1)
           ^^^^^^^^^^^^^^^^^^^^^^^^^^^^^^^^
  File "/nix/store/clx0mcir7qw8zk36zbr4jra789g3knf6-python3-3.11.10/lib/python3.11/socket.py", line 718, in readinto
    return self._sock.recv_into(b)
           ^^^^^^^^^^^^^^^^^^^^^^^
  File "/nix/store/clx0mcir7qw8zk36zbr4jra789g3knf6-python3-3.11.10/lib/python3.11/ssl.py", line 1314, in recv_into
    return self.read(nbytes, buffer)
           ^^^^^^^^^^^^^^^^^^^^^^^^^
  File "/nix/store/clx0mcir7qw8zk36zbr4jra789g3knf6-python3-3.11.10/lib/python3.11/ssl.py", line 1166, in read
    return self._sslobj.read(len, buffer)
           ^^^^^^^^^^^^^^^^^^^^^^^^^^^^^^
  File "/home/runner/workspace/.pythonlibs/lib/python3.11/site-packages/gunicorn/workers/base.py", line 199, in handle_quit
    sys.exit(0)
SystemExit: 0

During handling of the above exception, another exception occurred:

Traceback (most recent call last):
  File "/home/runner/workspace/.pythonlibs/lib/python3.11/site-packages/gunicorn/workers/sync.py", line 134, in handle
    self.handle_request(listener, req, client, addr)
  File "/home/runner/workspace/.pythonlibs/lib/python3.11/site-packages/gunicorn/workers/sync.py", line 177, in handle_request
    respiter = self.wsgi(environ, resp.start_response)
               ^^^^^^^^^^^^^^^^^^^^^^^^^^^^^^^^^^^^^^^
  File "/home/runner/workspace/.pythonlibs/lib/python3.11/site-packages/flask/app.py", line 1536, in __call__
    return self.wsgi_app(environ, start_response)
           ^^^^^^^^^^^^^^^^^^^^^^^^^^^^^^^^^^^^^^
  File "/home/runner/workspace/.pythonlibs/lib/python3.11/site-packages/flask/app.py", line 1511, in wsgi_app
    response = self.full_dispatch_request()
               ^^^^^^^^^^^^^^^^^^^^^^^^^^^^
  File "/home/runner/workspace/.pythonlibs/lib/python3.11/site-packages/flask/app.py", line 917, in full_dispatch_request
    rv = self.dispatch_request()
         ^^^^^^^^^^^^^^^^^^^^^^^
  File "/home/runner/workspace/.pythonlibs/lib/python3.11/site-packages/flask/app.py", line 902, in dispatch_request
    return self.ensure_sync(self.view_functions[rule.endpoint])(**view_args)  # type: ignore[no-any-return]
           ^^^^^^^^^^^^^^^^^^^^^^^^^^^^^^^^^^^^^^^^^^^^^^^^^^^^^^^^^^^^^^^^^
  File "/home/runner/workspace/auth.py", line 54, in login
    if send_otp_email(email, otp):
       ^^^^^^^^^^^^^^^^^^^^^^^^^^
  File "/home/runner/workspace/auth.py", line 28, in send_otp_email
    mail.send(msg)
  File "/home/runner/workspace/.pythonlibs/lib/python3.11/site-packages/flask_mail/__init__.py", line 539, in send
    with self.connect() as connection:
  File "/home/runner/workspace/.pythonlibs/lib/python3.11/site-packages/flask_mail/__init__.py", line 136, in __exit__
    self.host.quit()
  File "/nix/store/clx0mcir7qw8zk36zbr4jra789g3knf6-python3-3.11.10/lib/python3.11/smtplib.py", line 1004, in quit
    res = self.docmd("quit")
          ^^^^^^^^^^^^^^^^^^
  File "/nix/store/clx0mcir7qw8zk36zbr4jra789g3knf6-python3-3.11.10/lib/python3.11/smtplib.py", line 431, in docmd
    self.putcmd(cmd, args)
  File "/nix/store/clx0mcir7qw8zk36zbr4jra789g3knf6-python3-3.11.10/lib/python3.11/smtplib.py", line 378, in putcmd
    self.send(f'{s}{CRLF}')
  File "/nix/store/clx0mcir7qw8zk36zbr4jra789g3knf6-python3-3.11.10/lib/python3.11/smtplib.py", line 360, in send
    self.sock.sendall(s)
  File "/nix/store/clx0mcir7qw8zk36zbr4jra789g3knf6-python3-3.11.10/lib/python3.11/ssl.py", line 1273, in sendall
    v = self.send(byte_view[count:])
        ^^^^^^^^^^^^^^^^^^^^^^^^^^^^
  File "/nix/store/clx0mcir7qw8zk36zbr4jra789g3knf6-python3-3.11.10/lib/python3.11/ssl.py", line 1242, in send
    return self._sslobj.write(data)
           ^^^^^^^^^^^^^^^^^^^^^^^^
  File "/home/runner/workspace/.pythonlibs/lib/python3.11/site-packages/gunicorn/workers/base.py", line 199, in handle_quit
    sys.exit(0)
SystemExit: 0
[2025-03-27 14:14:54 +0000] [426] [INFO] Worker exiting (pid: 426)
[2025-03-27 14:14:54 +0000] [415] [INFO] Shutting down: Master
